<?xml version="1.0" encoding="utf-8"?>
<!-- This URDF was automatically created by SolidWorks to URDF Exporter! Originally created by Stephen Brawner (brawner@gmail.com) 
     Commit Version: 1.6.0-1-g15f4949  Build Version: 1.6.7594.29634
     For more information, please see http://wiki.ros.org/sw_urdf_exporter -->
<robot
  name="hello">
  <link
    name="base_link">
    <inertial>
      <origin
        xyz="-0.0115961375393338 0.141112194162708 4.16006760022607E-06"
        rpy="0 0 0" />
      <mass
        value="9.86715620266818" />
      <inertia
        ixx="0.132677989046086"
        ixy="-9.70160338003661E-05"
        ixz="-3.75107838296442E-07"
        iyy="0.260475914071983"
        iyz="6.96544013264117E-10"
        izz="0.137987912791742" />
    </inertial>
    <visual>
      <origin
        xyz="0 0 0"
        rpy="0 0 0" />
      <geometry>
        <mesh
          filename="package://hello/meshes/base_link.STL" />
      </geometry>
      <material
        name="">
        <color
          rgba="0.776470588235294 0.756862745098039 0.737254901960784 1" />
      </material>
    </visual>
    <collision>
      <origin
        xyz="0 0 0"
        rpy="0 0 0" />
      <geometry>
        <mesh
          filename="package://hello/meshes/base_link.STL" />
      </geometry>
    </collision>
  </link>
  <link
    name="Wheel1">
    <inertial>
      <origin
        xyz="0.0358925313422561 1.33013962899664E-08 -1.40306321785855E-06"
        rpy="0 0 0" />
      <mass
        value="1.08683454285844" />
      <inertia
        ixx="0.00199172568972123"
        ixy="4.18773380188281E-10"
        ixz="-4.24537357161986E-08"
        iyy="0.0010927579015596"
        iyz="-1.3053432125357E-10"
        izz="0.00109277152504694" />
    </inertial>
    <visual>
      <origin
        xyz="0 0 0"
        rpy="0 0 0" />
      <geometry>
        <mesh
          filename="package://hello/meshes/Wheel1.STL" />
      </geometry>
      <material
        name="">
        <color
          rgba="0.792156862745098 0.819607843137255 0.933333333333333 1" />
      </material>
    </visual>
    <collision>
      <origin
        xyz="0 0 0"
        rpy="0 0 0" />
      <geometry>
        <mesh
          filename="package://hello/meshes/Wheel1.STL" />
      </geometry>
    </collision>
  </link>
  <joint
    name="Wheel2"
    type="continuous">
    <origin
      xyz="-0.150000000000006 0.168 0.062499999999979"
      rpy="3.13669699771824 0 1.5707963267949" />
    <parent
      link="base_link" />
    <child
      link="Wheel1" />
    <axis
      xyz="1 0 0" />
  </joint>
  <link
    name="Wheel3">
    <inertial>
      <origin
        xyz="0.0358925313421825 1.41750076398939E-08 1.40305468546154E-06"
        rpy="0 0 0" />
      <mass
        value="1.08683454285396" />
      <inertia
        ixx="0.00199172568972123"
        ixy="4.12609301156856E-10"
        ixz="4.24537960605034E-08"
        iyy="0.00109275790167215"
        iyz="1.36281157753119E-10"
        izz="0.00109277152493439" />
    </inertial>
    <visual>
      <origin
        xyz="0 0 0"
        rpy="0 0 0" />
      <geometry>
        <mesh
          filename="package://hello/meshes/Wheel3.STL" />
      </geometry>
      <material
        name="">
        <color
          rgba="0.792156862745098 0.819607843137255 0.933333333333333 1" />
      </material>
    </visual>
    <collision>
      <origin
        xyz="0 0 0"
        rpy="0 0 0" />
      <geometry>
        <mesh
          filename="package://hello/meshes/Wheel3.STL" />
      </geometry>
    </collision>
  </link>
  <joint
    name="Wheel4"
    type="continuous">
    <origin
      xyz="-0.150000000000008 -0.168 0.062499999999968"
      rpy="-3.13669699771824 0 -1.5707963267949" />
    <parent
      link="base_link" />
    <child
      link="Wheel3" />
    <axis
      xyz="1 0 0" />
  </joint>
  <link
    name="Wheel5">
    <inertial>
      <origin
        xyz="0.0358925313422561 -4.36851138596595E-10 -1.40312619897887E-06"
        rpy="0 0 0" />
      <mass
        value="1.08683454285844" />
      <inertia
        ixx="0.00199172568972123"
        ixy="3.0821872261417E-12"
        ixz="-4.2455800992384E-08"
        iyy="0.0010927579003096"
        iyz="2.87399277655229E-12"
        izz="0.00109277152629695" />
    </inertial>
    <visual>
      <origin
        xyz="0 0 0"
        rpy="0 0 0" />
      <geometry>
        <mesh
          filename="package://hello/meshes/Wheel5.STL" />
      </geometry>
      <material
        name="">
        <color
          rgba="0.792156862745098 0.819607843137255 0.933333333333333 1" />
      </material>
    </visual>
    <collision>
      <origin
        xyz="0 0 0"
        rpy="0 0 0" />
      <geometry>
        <mesh
          filename="package://hello/meshes/Wheel5.STL" />
      </geometry>
    </collision>
  </link>
  <joint
    name="Wheel6"
    type="continuous">
    <origin
      xyz="0.150000000000006 -0.168 0.0624999999999788"
      rpy="-3.13669699771824 0 -1.5707963267949" />
    <parent
      link="base_link" />
    <child
      link="Wheel5" />
    <axis
      xyz="1 0 0" />
  </joint>
  <link
    name="Wheel7">
    <inertial>
      <origin
        xyz="0.0358925313421826 1.21536136293843E-06 7.01184832307966E-07"
        rpy="0 0 0" />
      <mass
        value="1.08683454285396" />
      <inertia
        ixx="0.00199172568972123"
        ixy="3.6766261093403E-08"
        ixz="2.1230569742561E-08"
        iyy="0.00109276812228902"
        iyz="5.89878862582486E-09"
        izz="0.00109276130431752" />
    </inertial>
    <visual>
      <origin
        xyz="0 0 0"
        rpy="0 0 0" />
      <geometry>
        <mesh
          filename="package://hello/meshes/Wheel7.STL" />
      </geometry>
      <material
        name="">
        <color
          rgba="0.650980392156863 0.619607843137255 0.588235294117647 1" />
      </material>
    </visual>
    <collision>
      <origin
        xyz="0 0 0"
        rpy="0 0 0" />
      <geometry>
        <mesh
          filename="package://hello/meshes/Wheel7.STL" />
      </geometry>
    </collision>
  </link>
  <joint
    name="Wheel8"
    type="continuous">
    <origin
      xyz="0.150000000000006 0.168 0.0624999999999788"
      rpy="-2.09929075826474 0 1.5707963267949" />
    <parent
      link="base_link" />
    <child
      link="Wheel7" />
    <axis
      xyz="1 0 0" />
  </joint>
  <link
    name="Lidar">
    <inertial>
      <origin
        xyz="-0.0074834698833364 0.0106681277328402 9.19261110886561E-05"
        rpy="0 0 0" />
      <mass
        value="1.33076913637071" />
      <inertia
        ixx="0.00061491794045409"
        ixy="0.00015824302591117"
        ixz="8.01984318975301E-07"
        iyy="0.00109815200027136"
        iyz="3.0916298658758E-06"
        izz="0.000960697335617222" />
    </inertial>
    <visual>
      <origin
        xyz="0 0 0"
        rpy="0 0 0" />
      <geometry>
        <mesh
          filename="package://hello/meshes/Lidar.STL" />
      </geometry>
      <material
        name="">
        <color
          rgba="0.792156862745098 0.819607843137255 0.933333333333333 1" />
      </material>
    </visual>
    <collision>
      <origin
        xyz="0 0 0"
        rpy="0 0 0" />
      <geometry>
        <mesh
          filename="package://hello/meshes/Lidar.STL" />
      </geometry>
    </collision>
  </link>
  <joint
    name="Lidar1"
    type="fixed">
    <origin
      xyz="-0.19775 0 0.194099999999983"
      rpy="1.5707963267949 0 0" />
    <parent
      link="base_link" />
    <child
      link="Lidar" />
    <axis
      xyz="0 0 0" />
  </joint>
</robot>